Workbook

Sheet retail_sales_dataset
A1: Transaction ID | B1: Date | C1: Customer ID | D1: Gender | E1: Age | F1: Product Category | G1: Quantity | H1: Price per Unit | I1: Total Sales | J1: Commision 2023 | K1: Generation | L1: Concatenate
A2: 1 | B2: 45254 | C2: CUST001 | D2: Male | E2: 34 | F2: Beauty | G2: 3 | H2: 50 | I2: =G2*H2 -> 150 | J2: =I2*$O$3 -> 2.25 | K2: =IF(RetailSales[[#This Row],[Age]]<30,"Young Adult",IF(RetailSales[[#This Row],[Age]]<50,"Adult","Senior")) -> Adult | L2: =_xlfn.CONCAT(I2,"_",RetailSales[[#This Row],[Product Category]]) -> 150_Beauty | O2: rate %
A3: 2 | B3: 44984 | C3: CUST002 | D3: Female | E3: 26 | F3: Clothing | G3: 2 | H3: 500 | I3: =G3*H3 -> 1000 | J3: =I3*$O$3 -> 15 | K3: =IF(RetailSales[[#This Row],[Age]]<30,"Young Adult",IF(RetailSales[[#This Row],[Age]]<50,"Adult","Senior")) -> Young Adult | L3: =_xlfn.CONCAT(I3,"_",RetailSales[[#This Row],[Product Category]]) -> 1000_Clothing | N3: Commision 2023 | O3: 0.015
A4: 3 | B4: 44939 | C4: CUST003 | D4: Male | E4: 50 | F4: Electronics | G4: 1 | H4: 30 | I4: =G4*H4 -> 30 | J4: =I4*$O$3 -> 0.45 | K4: =IF(RetailSales[[#This Row],[Age]]<30,"Young Adult",IF(RetailSales[[#This Row],[Age]]<50,"Adult","Senior")) -> Senior | L4: =_xlfn.CONCAT(I4,"_",RetailSales[[#This Row],[Product Category]]) -> 30_Electronics | N4: Commision 2024 | O4: 0.02
A5: 4 | B5: 45067 | C5: CUST004 | D5: Male | E5: 37 | F5: Clothing | G5: 1 | H5: 500 | I5: =G5*H5 -> 500 | J5: =I5*$O$3 -> 7.5 | K5: =IF(RetailSales[[#This Row],[Age]]<30,"Young Adult",IF(RetailSales[[#This Row],[Age]]<50,"Adult","Senior")) -> Adult | L5: =_xlfn.CONCAT(I5,"_",RetailSales[[#This Row],[Product Category]]) -> 500_Clothing
A6: 5 | B6: 45052 | C6: CUST005 | D6: Male | E6: 30 | F6: Beauty | G6: 2 | H6: 50 | I6: =G6*H6 -> 100 | J6: =I6*$O$3 -> 1.5 | K6: =IF(RetailSales[[#This Row],[Age]]<30,"Young Adult",IF(RetailSales[[#This Row],[Age]]<50,"Adult","Senior")) -> Adult | L6: =_xlfn.CONCAT(I6,"_",RetailSales[[#This Row],[Product Category]]) -> 100_Beauty
A7: 6 | B7: 45041 | C7: CUST006 | D7: Female | E7: 45 | F7: Beauty | G7: 1 | H7: 30 | I7: =G7*H7 -> 30 | J7: =I7*$O$3 -> 0.45 | K7: =IF(RetailSales[[#This Row],[Age]]<30,"Young Adult",IF(RetailSales[[#This Row],[Age]]<50,"Adult","Senior")) -> Adult | L7: =_xlfn.CONCAT(I7,"_",RetailSales[[#This Row],[Product Category]]) -> 30_Beauty
A8: 7 | B8: 44998 | C8: CUST007 | D8: Male | E8: 46 | F8: Clothing | G8: 2 | H8: 25 | I8: =G8*H8 -> 50 | J8: =I8*$O$3 -> 0.75 | K8: =IF(RetailSales[[#This Row],[Age]]<30,"Young Adult",IF(RetailSales[[#This Row],[Age]]<50,"Adult","Senior")) -> Adult | L8: =_xlfn.CONCAT(I8,"_",RetailSales[[#This Row],[Product Category]]) -> 50_Clothing
A9: 8 | B9: 44979 | C9: CUST008 | D9: Male | E9: 30 | F9: Electronics | G9: 4 | H9: 25 | I9: =G9*H9 -> 100 | J9: =I9*$O$3 -> 1.5 | K9: =IF(RetailSales[[#This Row],[Age]]<30,"Young Adult",IF(RetailSales[[#This Row],[Age]]<50,"Adult","Senior")) -> Adult | L9: =_xlfn.CONCAT(I9,"_",RetailSales[[#This Row],[Product Category]]) -> 100_Electronics
A10: 9 | B10: 45273 | C10: CUST009 | D10: Male | E10: 63 | F10: Electronics | G10: 2 | H10: 300 | I10: =G10*H10 -> 600 | J10: =I10*$O$3 -> 9 | K10: =IF(RetailSales[[#This Row],[Age]]<30,"Young Adult",IF(RetailSales[[#This Row],[Age]]<50,"Adult","Senior")) -> Senior | L10: =_xlfn.CONCAT(I10,"_",RetailSales[[#This Row],[Product Category]]) -> 600_Electronics | O10: Comission Total | P10: =SUM(J2:J1001) -> 6840
A11: 10 | B11: 45206 | C11: CUST010 | D11: Female | E11: 52 | F11: Clothing | G11: 4 | H11: 50 | I11: =G11*H11 -> 200 | J11: =I11*$O$3 -> 3 | K11: =IF(RetailSales[[#This Row],[Age]]<30,"Young Adult",IF(RetailSales[[#This Row],[Age]]<50,"Adult","Senior")) -> Senior | L11: =_xlfn.CONCAT(I11,"_",RetailSales[[#This Row],[Product Category]]) -> 200_Clothing | O11: Average Commision | P11: =AVERAGE(J2:J1001) -> 6.84
A12: 11 | B12: 44971 | C12: CUST011 | D12: Male | E12: 23 | F12: Clothing | G12: 2 | H12: 50 | I12: =G12*H12 -> 100 | J12: =I12*$O$3 -> 1.5 | K12: =IF(RetailSales[[#This Row],[Age]]<30,"Young Adult",IF(RetailSales[[#This Row],[Age]]<50,"Adult","Senior")) -> Young Adult | L12: =_xlfn.CONCAT(I12,"_",RetailSales[[#This Row],[Product Category]]) -> 100_Clothing
A13: 12 | B13: 45229 | C13: CUST012 | D13: Male | E13: 35 | F13: Beauty | G13: 3 | H13: 25 | I13: =G13*H13 -> 75 | J13: =I13*$O$3 -> 1.125 | K13: =IF(RetailSales[[#This Row],[Age]]<30,"Young Adult",IF(RetailSales[[#This Row],[Age]]<50,"Adult","Senior")) -> Adult | L13: =_xlfn.CONCAT(I13,"_",RetailSales[[#This Row],[Product Category]]) -> 75_Beauty
A14: 13 | B14: 45143 | C14: CUST013 | D14: Male | E14: 22 | F14: Electronics | G14: 3 | H14: 500 | I14: =G14*H14 -> 1500 | J14: =I14*$O$3 -> 22.5 | K14: =IF(RetailSales[[#This Row],[Age]]<30,"Young Adult",IF(RetailSales[[#This Row],[Age]]<50,"Adult","Senior")) -> Young Adult | L14: =_xlfn.CONCAT(I14,"_",RetailSales[[#This Row],[Product Category]]) -> 1500_Electronics
A15: 14 | B15: 44943 | C15: CUST014 | D15: Male | E15: 64 | F15: Clothing | G15: 4 | H15: 30 | I15: =G15*H15 -> 120 | J15: =I15*$O$3 -> 1.8 | K15: =IF(RetailSales[[#This Row],[Age]]<30,"Young Adult",IF(RetailSales[[#This Row],[Age]]<50,"Adult","Senior")) -> Senior | L15: =_xlfn.CONCAT(I15,"_",RetailSales[[#This Row],[Product Category]]) -> 120_Clothing
A16: 15 | B16: 44942 | C16: CUST015 | D16: Female | E16: 42 | F16: Electronics | G16: 4 | H16: 500 | I16: =G16*H16 -> 2000 | J16: =I16*$O$3 -> 30 | K16: =IF(RetailSales[[#This Row],[Age]]<30,"Young Adult",IF(RetailSales[[#This Row],[Age]]<50,"Adult","Senior")) -> Adult | L16: =_xlfn.CONCAT(I16,"_",RetailSales[[#This Row],[Product Category]]) -> 2000_Electronics | P16: Quantity
A17: 16 | B17: 44974 | C17: CUST016 | D17: Male | E17: 19 | F17: Clothing | G17: 3 | H17: 500 | I17: =G17*H17 -> 1500 | J17: =I17*$O$3 -> 22.5 | K17: =IF(RetailSales[[#This Row],[Age]]<30,"Young Adult",IF(RetailSales[[#This Row],[Age]]<50,"Adult","Senior")) -> Young Adult | L17: =_xlfn.CONCAT(I17,"_",RetailSales[[#This Row],[Product Category]]) -> 1500_Clothing | O17: Total | P17: Male | Q17: Female | R17: Average Sales | U17: Transactions | V17: Product Categories
A18: 17 | B18: 45038 | C18: CUST017 | D18: Female | E18: 27 | F18: Clothing | G18: 4 | H18: 25 | I18: =G18*H18 -> 100 | J18: =I18*$O$3 -> 1.5 | K18: =IF(RetailSales[[#This Row],[Age]]<30,"Young Adult",IF(RetailSales[[#This Row],[Age]]<50,"Adult","Senior")) -> Young Adult | L18: =_xlfn.CONCAT(I18,"_",RetailSales[[#This Row],[Product Category]]) -> 100_Clothing | N18: All products | O18: =SUM(I:I) -> 456000 | P18: =SUMIF(RetailSales[Gender],P17,RetailSales[Quantity]) -> 1216 | Q18: =SUMIF(RetailSales[Gender],Q17,RetailSales[Quantity]) -> 1298 | R18: =AVERAGE(I2:I1001) -> 456 | T18: COUNT | U18: =COUNT(RetailSales[Transaction ID]) -> 1000 | V18: =COUNT(RetailSales[Product Category]) -> 0
A19: 18 | B19: 45046 | C19: CUST018 | D19: Female | E19: 47 | F19: Electronics | G19: 2 | H19: 25 | I19: =G19*H19 -> 50 | J19: =I19*$O$3 -> 0.75 | K19: =IF(RetailSales[[#This Row],[Age]]<30,"Young Adult",IF(RetailSales[[#This Row],[Age]]<50,"Adult","Senior")) -> Adult | L19: =_xlfn.CONCAT(I19,"_",RetailSales[[#This Row],[Product Category]]) -> 50_Electronics | N19: {=_xlfn.UNIQUE(RetailSales[Product Category])} -> Beauty | O19: =SUMIF(RetailSales[Product Category],N19,I$2:I$1001) -> 143515 | P19: =SUMIFS(RetailSales[Quantity],RetailSales[Product Category],N19,RetailSales[Gender],$P$17) -> 353 | Q19: =SUMIFS(RetailSales[Quantity],RetailSales[Product Category],N19,RetailSales[Gender],$Q$17) -> 418 | R19: =AVERAGEIF(RetailSales[Product Category],N19,$I$2:$I$1001) -> 467.47557 | T19: COUNTA | U19: =COUNTA(RetailSales[Transaction ID]) -> 1000 | V19: =COUNTA(RetailSales[Product Category]) -> 1000
A20: 19 | B20: 45185 | C20: CUST019 | D20: Female | E20: 62 | F20: Clothing | G20: 2 | H20: 25 | I20: =G20*H20 -> 50 | J20: =I20*$O$3 -> 0.75 | K20: =IF(RetailSales[[#This Row],[Age]]<30,"Young Adult",IF(RetailSales[[#This Row],[Age]]<50,"Adult","Senior")) -> Senior | L20: =_xlfn.CONCAT(I20,"_",RetailSales[[#This Row],[Product Category]]) -> 50_Clothing | N20: Clothing | O20: =SUMIF(RetailSales[Product Category],N20,I$2:I$1001) -> 155580 | P20: =SUMIFS(RetailSales[Quantity],RetailSales[Product Category],N20,RetailSales[Gender],$P$17) -> 453 | Q20: =SUMIFS(RetailSales[Quantity],RetailSales[Product Category],N20,RetailSales[Gender],$Q$17) -> 441 | R20: =AVERAGEIF(RetailSales[Product Category],N20,$I$2:$I$1001) -> 443.24786 | T20: COUNTBLANK | U20: =COUNTBLANK(RetailSales[Transaction ID]) -> 0 | V20: =COUNTBLANK(RetailSales[Product Category]) -> 0
A21: 20 | B21: 45235 | C21: CUST020 | D21: Male | E21: 22 | F21: Clothing | G21: 3 | H21: 300 | I21: =G21*H21 -> 900 | J21: =I21*$O$3 -> 13.5 | K21: =IF(RetailSales[[#This Row],[Age]]<30,"Young Adult",IF(RetailSales[[#This Row],[Age]]<50,"Adult","Senior")) -> Young Adult | L21: =_xlfn.CONCAT(I21,"_",RetailSales[[#This Row],[Product Category]]) -> 900_Clothing | N21: Electronics | O21: =SUMIF(RetailSales[Product Category],N21,I$2:I$1001) -> 156905 | P21: =SUMIFS(RetailSales[Quantity],RetailSales[Product Category],N21,RetailSales[Gender],$P$17) -> 410 | Q21: =SUMIFS(RetailSales[Quantity],RetailSales[Product Category],N21,RetailSales[Gender],$Q$17) -> 439 | R21: =AVERAGEIF(RetailSales[Product Category],N21,$I$2:$I$1001) -> 458.78655
A22: 21 | B22: 44940 | C22: CUST021 | D22: Female | E22: 50 | F22: Beauty | G22: 1 | H22: 500 | I22: =G22*H22 -> 500 | J22: =I22*$O$3 -> 7.5 | K22: =IF(RetailSales[[#This Row],[Age]]<30,"Young Adult",IF(RetailSales[[#This Row],[Age]]<50,"Adult","Senior")) -> Senior | L22: =_xlfn.CONCAT(I22,"_",RetailSales[[#This Row],[Product Category]]) -> 500_Beauty
A23: 22 | B23: 45214 | C23: CUST022 | D23: Male | E23: 18 | F23: Clothing | G23: 2 | H23: 50 | I23: =G23*H23 -> 100 | J23: =I23*$O$3 -> 1.5 | K23: =IF(RetailSales[[#This Row],[Age]]<30,"Young Adult",IF(RetailSales[[#This Row],[Age]]<50,"Adult","Senior")) -> Young Adult | L23: =_xlfn.CONCAT(I23,"_",RetailSales[[#This Row],[Product Category]]) -> 100_Clothing
A24: 23 | B24: 45028 | C24: CUST023 | D24: Female | E24: 35 | F24: Clothing | G24: 4 | H24: 30 | I24: =G24*H24 -> 120 | J24: =I24*$O$3 -> 1.8 | K24: =IF(RetailSales[[#This Row],[Age]]<30,"Young Adult",IF(RetailSales[[#This Row],[Age]]<50,"Adult","Senior")) -> Adult | L24: =_xlfn.CONCAT(I24,"_",RetailSales[[#This Row],[Product Category]]) -> 120_Clothing
A25: 24 | B25: 45259 | C25: CUST024 | D25: Female | E25: 49 | F25: Clothing | G25: 1 | H25: 300 | I25: =G25*H25 -> 300 | J25: =I25*$O$3 -> 4.5 | K25: =IF(RetailSales[[#This Row],[Age]]<30,"Young Adult",IF(RetailSales[[#This Row],[Age]]<50,"Adult","Senior")) -> Adult | L25: =_xlfn.CONCAT(I25,"_",RetailSales[[#This Row],[Product Category]]) -> 300_Clothing
A26: 25 | B26: 45286 | C26: CUST025 | D26: Female | E26: 64 | F26: Beauty | G26: 1 | H26: 50 | I26: =G26*H26 -> 50 | J26: =I26*$O$3 -> 0.75 | K26: =IF(RetailSales[[#This Row],[Age]]<30,"Young Adult",IF(RetailSales[[#This Row],[Age]]<50,"Adult","Senior")) -> Senior | L26: =_xlfn.CONCAT(I26,"_",RetailSales[[#This Row],[Product Category]]) -> 50_Beauty
A27: 26 | B27: 45206 | C27: CUST026 | D27: Female | E27: 28 | F27: Electronics | G27: 2 | H27: 500 | I27: =G27*H27 -> 1000 | J27: =I27*$O$3 -> 15 | K27: =IF(RetailSales[[#This Row],[Age]]<30,"Young Adult",IF(RetailSales[[#This Row],[Age]]<50,"Adult","Senior")) -> Young Adult | L27: =_xlfn.CONCAT(I27,"_",RetailSales[[#This Row],[Product Category]]) -> 1000_Electronics
A28: 27 | B28: 45141 | C28: CUST027 | D28: Female | E28: 38 | F28: Beauty | G28: 2 | H28: 25 | I28: =G28*H28 -> 50 | J28: =I28*$O$3 -> 0.75 | K28: =IF(RetailSales[[#This Row],[Age]]<30,"Young Adult",IF(RetailSales[[#This Row],[Age]]<50,"Adult","Senior")) -> Adult | L28: =_xlfn.CONCAT(I28,"_",RetailSales[[#This Row],[Product Category]]) -> 50_Beauty
A29: 28 | B29: 45039 | C29: CUST028 | D29: Female | E29: 43 | F29: Beauty | G29: 1 | H29: 500 | I29: =G29*H29 -> 500 | J29: =I29*$O$3 -> 7.5 | K29: =IF(RetailSales[[#This Row],[Age]]<30,"Young Adult",IF(RetailSales[[#This Row],[Age]]<50,"Adult","Senior")) -> Adult | L29: =_xlfn.CONCAT(I29,"_",RetailSales[[#This Row],[Product Category]]) -> 500_Beauty
A30: 29 | B30: 45156 | C30: CUST029 | D30: Female | E30: 42 | F30: Electronics | G30: 1 | H30: 30 | I30: =G30*H30 -> 30 | J30: =I30*$O$3 -> 0.45 | K30: =IF(RetailSales[[#This Row],[Age]]<30,"Young Adult",IF(RetailSales[[#This Row],[Age]]<50,"Adult","Senior")) -> Adult | L30: =_xlfn.CONCAT(I30,"_",RetailSales[[#This Row],[Product Category]]) -> 30_Electronics
A31: 30 | B31: 45228 | C31: CUST030 | D31: Female | E31: 39 | F31: Beauty | G31: 3 | H31: 300 | I31: =G31*H31 -> 900 | J31: =I31*$O$3 -> 13.5 | K31: =IF(RetailSales[[#This Row],[Age]]<30,"Young Adult",IF(RetailSales[[#This Row],[Age]]<50,"Adult","Senior")) -> Adult | L31: =_xlfn.CONCAT(I31,"_",RetailSales[[#This Row],[Product Category]]) -> 900_Beauty
A32: 31 | B32: 45069 | C32: CUST031 | D32: Male | E32: 44 | F32: Electronics | G32: 4 | H32: 300 | I32: =G32*H32 -> 1200 | J32: =I32*$O$3 -> 18 | K32: =IF(RetailSales[[#This Row],[Age]]<30,"Young Adult",IF(RetailSales[[#This Row],[Age]]<50,"Adult","Senior")) -> Adult | L32: =_xlfn.CONCAT(I32,"_",RetailSales[[#This Row],[Product Category]]) -> 1200_Electronics
A33: 32 | B33: 44930 | C33: CUST032 | D33: Male | E33: 30 | F33: Beauty | G33: 3 | H33: 30 | I33: =G33*H33 -> 90 | J33: =I33*$O$3 -> 1.35 | K33: =IF(RetailSales[[#This Row],[Age]]<30,"Young Adult",IF(RetailSales[[#This Row],[Age]]<50,"Adult","Senior")) -> Adult | L33: =_xlfn.CONCAT(I33,"_",RetailSales[[#This Row],[Product Category]]) -> 90_Beauty
... A1001: 1000 | B1001: 45028 | C1001: CUST1000 | D1001: Male | E1001: 47 | F1001: Electronics | G1001: 4 | H1001: 30 | I1001: =G1001*H1001 -> 120 | J1001: =I1001*$O$3 -> 1.8 | K1001: =IF(RetailSales[[#This Row],[Age]]<30,"Young Adult",IF(RetailSales[[#This Row],[Age]]<50,"Adult","Senior")) -> Adult | L1001: =_xlfn.CONCAT(I1001,"_",RetailSales[[#This Row],[Product Category]]) -> 120_Electronics
X1005: Product category legend | AA1005: Generation legend
X1006: {=_xlfn.UNIQUE(RetailSales[Product Category])} -> Beauty | Y1006: =LEFT(X1006,1) -> B | AA1006: {=_xlfn.UNIQUE(K2:K1001)} -> Adult | AB1006: =LEFT(AA1006,1) -> A
X1007: Clothing | Y1007: =LEFT(X1007,1) -> C | AA1007: Young Adult | AB1007: {=_xlfn.TEXTJOIN("",TRUE,LEFT(_xlfn.TEXTSPLIT(AA1007," "),1))} -> YA
X1008: Electronics | Y1008: =LEFT(X1008,1) -> E | AA1008: Senior | AB1008: =LEFT(AA1008,1) -> S
W1015: Who Spends More? A Comparison by Gender, Generation, and Product Category
W1016: Gender | X1016: Male | AG1016: Female
...

Sheet Transactions
A1: Transaction ID | B1: Total Sales | C1: Product category | D1: Another way
A2: 10 | B2: =VLOOKUP(A2,retail_sales_dataset!$A$2:$J$1001,COLUMN(retail_sales_dataset!$I$1),FALSE) -> 200 | C2: =VLOOKUP(A2,RetailSales[],COLUMN(RetailSales[[#This Row],[Product Category]]),FALSE) -> Clothing | D2: =VLOOKUP(A2,retail_sales_dataset!A:J,9,FALSE) -> 200
A3: 15 | B3: =VLOOKUP(A3,retail_sales_dataset!$A$2:$J$1001,COLUMN(retail_sales_dataset!$I$1),FALSE) -> 2000 | C3: =VLOOKUP(A3,RetailSales[],COLUMN(RetailSales[[#This Row],[Product Category]]),FALSE) -> Electronics | D3: =VLOOKUP(A3,retail_sales_dataset!A:J,9,FALSE) -> 2000
A4: 25 | B4: =VLOOKUP(A4,retail_sales_dataset!$A$2:$J$1001,COLUMN(retail_sales_dataset!$I$1),FALSE) -> 50 | C4: =VLOOKUP(A4,RetailSales[],COLUMN(RetailSales[[#This Row],[Product Category]]),FALSE) -> Beauty | D4: =VLOOKUP(A4,retail_sales_dataset!A:J,9,FALSE) -> 50
A5: 30 | B5: =VLOOKUP(A5,retail_sales_dataset!$A$2:$J$1001,COLUMN(retail_sales_dataset!$I$1),FALSE) -> 900 | C5: =VLOOKUP(A5,RetailSales[],COLUMN(RetailSales[[#This Row],[Product Category]]),FALSE) -> Beauty | D5: =VLOOKUP(A5,retail_sales_dataset!A:J,9,FALSE) -> 900
A6: 54 | B6: =VLOOKUP(A6,retail_sales_dataset!$A$2:$J$1001,COLUMN(retail_sales_dataset!$I$1),FALSE) -> 1500 | C6: =VLOOKUP(A6,RetailSales[],COLUMN(RetailSales[[#This Row],[Product Category]]),FALSE) -> Electronics | D6: =VLOOKUP(A6,retail_sales_dataset!A:J,9,FALSE) -> 1500
A7: 55 | B7: =VLOOKUP(A7,retail_sales_dataset!$A$2:$J$1001,COLUMN(retail_sales_dataset!$I$1),FALSE) -> 120 | C7: =VLOOKUP(A7,RetailSales[],COLUMN(RetailSales[[#This Row],[Product Category]]),FALSE) -> Beauty | D7: =VLOOKUP(A7,retail_sales_dataset!A:J,9,FALSE) -> 120
A8: 67 | B8: =VLOOKUP(A8,retail_sales_dataset!$A$2:$J$1001,COLUMN(retail_sales_dataset!$I$1),FALSE) -> 1200 | C8: =VLOOKUP(A8,RetailSales[],COLUMN(RetailSales[[#This Row],[Product Category]]),FALSE) -> Beauty | D8: =VLOOKUP(A8,retail_sales_dataset!A:J,9,FALSE) -> 1200
A9: 89 | B9: =VLOOKUP(A9,retail_sales_dataset!$A$2:$J$1001,COLUMN(retail_sales_dataset!$I$1),FALSE) -> 2000 | C9: =VLOOKUP(A9,RetailSales[],COLUMN(RetailSales[[#This Row],[Product Category]]),FALSE) -> Electronics | D9: =VLOOKUP(A9,retail_sales_dataset!A:J,9,FALSE) -> 2000
A10: 100 | B10: =VLOOKUP(A10,retail_sales_dataset!$A$2:$J$1001,COLUMN(retail_sales_dataset!$I$1),FALSE) -> 30 | C10: =VLOOKUP(A10,RetailSales[],COLUMN(RetailSales[[#This Row],[Product Category]]),FALSE) -> Electronics | D10: =VLOOKUP(A10,retail_sales_dataset!A:J,9,FALSE) -> 30

Sheet Task 2
A1: Student name | B1: English | C1: Mathematics | D1: Science | E1: Average | F1: Highest score | G1: Additional support
A2: Ted | B2: 80 | C2: 75 | D2: 90 | E2: =AVERAGE(Table1[[#This Row],[English]:[Science]]) -> 81.666667 | F2: =MAX(Table1[[#This Row],[English]:[Science]]) -> 90 | G2: No
A3: Linda | B3: 90 | C3: 50 | D3: 70 | E3: =AVERAGE(Table1[[#This Row],[English]:[Science]]) -> 70 | F3: =MAX(Table1[[#This Row],[English]:[Science]]) -> 90 | G3: No
A4: Carol | B4: 75 | C4: 85 | D4: 85 | E4: =AVERAGE(Table1[[#This Row],[English]:[Science]]) -> 81.666667 | F4: =MAX(Table1[[#This Row],[English]:[Science]]) -> 85 | G4: No
A5: Khan | B5: 85 | C5: 75 | D5: 80 | E5: =AVERAGE(Table1[[#This Row],[English]:[Science]]) -> 80 | F5: =MAX(Table1[[#This Row],[English]:[Science]]) -> 85 | G5: No
A6: Harry | B6: 80 | C6: 70 | D6: 80 | E6: =AVERAGE(Table1[[#This Row],[English]:[Science]]) -> 76.666667 | F6: =MAX(Table1[[#This Row],[English]:[Science]]) -> 80 | G6: No
A7: Sarah | B7: 80 | C7: 70 | D7: 80 | E7: =AVERAGE(Table1[[#This Row],[English]:[Science]]) -> 76.666667 | F7: =MAX(Table1[[#This Row],[English]:[Science]]) -> 80 | G7: No
A8: John | B8: 65 | C8: 80 | D8: 70 | E8: =AVERAGE(Table1[[#This Row],[English]:[Science]]) -> 71.666667 | F8: =MAX(Table1[[#This Row],[English]:[Science]]) -> 80 | G8: No
A9: Edward | B9: 55 | C9: 80 | D9: 60 | E9: =AVERAGE(Table1[[#This Row],[English]:[Science]]) -> 65 | F9: =MAX(Table1[[#This Row],[English]:[Science]]) -> 80 | G9: Yes
A10: Mary | B10: 55 | C10: 70 | D10: 65 | E10: =AVERAGE(Table1[[#This Row],[English]:[Science]]) -> 63.333333 | F10: =MAX(Table1[[#This Row],[English]:[Science]]) -> 70 | G10: Yes
A11: Thomas | B11: 55 | C11: 30 | D11: 65 | E11: =AVERAGE(Table1[[#This Row],[English]:[Science]]) -> 50 | F11: =MAX(Table1[[#This Row],[English]:[Science]]) -> 65 | G11: Yes
A15: Task
A16: 1) Apply filter and sorting to show the best students in each subject.
A17: 2) Calculate the average for all students and fill into Column E. (Use formula)
A18: 3) Using the =MAX fucntion, tell me what the students highest score was in column F.
A19: 4) Apply filter and sorting to show the best student in this classroom by average.
A20: 5) Apply filter and sorting to show the best student in this classroom by highest score.
A21: 6) Use conditional formatting to clearly identify the highest and lowest average scores
